Workbook

Sheet README
A1: Golden Delta Bank - starter data (SIMULATION, sample numbers only)
A2: All people, banks, rates and tax rates are made up. Business date is 2026-10-13 (the day after the last sample end of day, 2026-10-12). Opening balances are dated 2026-09-30; sample activity runs 2026-10-01 to 2026-10-12.
A4: Sheet | B4: Table | C4: Rows | D4: Stage
A5: Config | B5: tblConfig | C5: =COUNTA(Config!A:A)-1 -> 13 | D5: 1
A6: Users | B6: tblUsers | C6: =COUNTA(Users!A:A)-1 -> 49 | D6: 1
A7: Branches | B7: tblBranches | C7: =COUNTA(Branches!A:A)-1 -> 15 | D7: 1
A8: Customers | B8: tblCustomers | C8: =COUNTA(Customers!A:A)-1 -> 320 | D8: 1
A9: Products | B9: tblProducts | C9: =COUNTA(Products!A:A)-1 -> 5 | D9: 1
A10: RateTiers | B10: tblRateTiers | C10: =COUNTA(RateTiers!A:A)-1 -> 48 | D10: 1
A11: Fees | B11: tblFees | C11: =COUNTA(Fees!A:A)-1 -> 7 | D11: 1
A12: OtherBanks | B12: tblOtherBanks | C12: =COUNTA(OtherBanks!A:A)-1 -> 4 | D12: 1
A13: Chart | B13: tblChart | C13: =COUNTA(Chart!A:A)-1 -> 50 | D13: 1
A14: Accounts | B14: tblAccounts | C14: =COUNTA(Accounts!A:A)-1 -> 447 | D14: 1
A15: Transactions | B15: tblTransactions | C15: =COUNTA(Transactions!A:A)-1 -> 1337 | D15: 1
A16: InterbankTransfers | B16: tblInterbankTransfers | C16: =COUNTA(InterbankTransfers!A:A)-1 -> 36 | D16: 1
A17: Approvals | B17: tblApprovals | C17: =COUNTA(Approvals!A:A)-1 -> 9 | D17: 1
A18: Journal | B18: tblJournal | C18: =COUNTA(Journal!A:A)-1 -> 703 | D18: 1
A19: JournalLines | B19: tblJournalLines | C19: =COUNTA(JournalLines!A:A)-1 -> 2389 | D19: 1
A20: DailyClose | B20: tblDailyClose | C20: =COUNTA(DailyClose!A:A)-1 -> 12 | D20: 1
A21: Audit | B21: tblAudit | C21: =COUNTA(Audit!A:A)-1 -> 0 | D21: 1
A22: Log | B22: tblLog | C22: =COUNTA(Log!A:A)-1 -> 0 | D22: 1
A23: Currencies | B23: tblCurrencies | C23: =COUNTA(Currencies!A:A)-1 -> 5 | D23: 6 (reference)
A24: ExchangeRates | B24: tblExchangeRates | C24: =COUNTA(ExchangeRates!A:A)-1 -> 120 | D24: 6 (reference)
A25: TaxRates | B25: tblTaxRates | C25: =COUNTA(TaxRates!A:A)-1 -> 4 | D25: 2 (reference)
A26: BranchCosts | B26: tblBranchCosts | C26: =COUNTA(BranchCosts!A:A)-1 -> 150 | D26: 2 (reference)
A27: FixedAssets | B27: tblFixedAssets | C27: =COUNTA(FixedAssets!A:A)-1 -> 89 | D27: 2 (reference)
A29: Trial balance at 2026-10-13 (before the first end of day) | B29: Debit - Credit
A30: 1000 Cash in vault | B30: 4714385127
A31: 1100 Treasury and settlement balances | B31: 18772303480
A32: 2000 Savings deposits | B32: -1476938571
A33: 2010 Current account deposits | B33: -1315667248
A34: 2020 Fixed deposits | B34: -693575910
A35: 2900 Interbank payable (simulated) | B35: -427367
A36: 3000 Share capital | B36: -20000000000
A37: 4100 Fee income | B37: -79511
A38: Sum of all GL balances (must be 0) | B38: =SUM(B30:B37) -> 0
A40: What the first end of day (13 Oct) should do
A41: Fixed deposits maturing on 13 Oct: 2 | B41: 0060000398: principal 14,192,339, gross interest 214,635, tax 21,464, net 193,171; 0130000399: principal 9,473,371, gross interest 143,269, tax 14,327, net 128,942
A42: Accounts that become Dormant: 2 | B42: 0120000122, 0020000330
A43: Interbank transfers due to settle: 1 | B43: IB000035 (each settles or fails; sample failure rates apply)
...

Sheet Config
A1: Key | B1: Value
A2: BankName | B2: Golden Delta Bank (SIMULATION)
A3: BaseCurrency | B3: MMK
A4: BusinessDate | B4: 2026-10-13
A5: PolicyRate | B5: 0.10
A6: WithholdingTaxRate | B6: 0.10
A7: TellerLimit | B7: 5000000
A8: BranchManagerLimit | B8: 50000000
A9: DailyWithdrawalLimit | B9: 20000000
A10: DormantDays | B10: 365
A11: EarlyBreakRate | B11: 0.03
A12: DayCountBasis | B12: 365
... A14: ReserveRatio | B14: 0.05

Sheet Users
A1: UserID | B1: Name | C1: Role | D1: BranchID | E1: IsActive
A2: U001 | B2: System Admin | C2: Admin | D2: BR001 | E2: Yes
A3: U002 | B3: HO Officer 1 | C3: HeadOffice | D3: BR001 | E3: Yes
A4: U003 | B4: HO Officer 2 | C4: HeadOffice | D4: BR001 | E4: Yes
A5: U004 | B5: Internal Auditor | C5: Auditor | D5: BR001 | E5: Yes
A6: U005 | B6: Thura Su Lat | C6: Teller | D6: BR001 | E6: Yes
A7: U006 | B7: San Thu Soe | C7: Teller | D7: BR001 | E7: Yes
A8: U007 | B8: Zaw Min Soe | C8: BranchManager | D8: BR001 | E8: Yes
A9: U008 | B9: Htoo Thant Lwin | C9: Teller | D9: BR002 | E9: Yes
A10: U009 | B10: Htet Lin Swe | C10: Teller | D10: BR002 | E10: Yes
A11: U010 | B11: Mya Thu Naing | C11: BranchManager | D11: BR002 | E11: Yes
A12: U011 | B12: Ye Naing Maung | C12: Teller | D12: BR003 | E12: Yes
... A50: U049 | B50: Tun Thant Tun | C50: BranchManager | D50: BR015 | E50: Yes

Sheet Branches
A1: BranchID | B1: Name | C1: Type | D1: City | E1: Region | F1: PremisesType | G1: OpenDate | H1: Status | I1: VaultMin | J1: VaultMax
A2: BR001 | B2: Head Office | C2: HeadOffice | D2: Yangon | E2: Yangon Region | F2: Owned | G2: 39539 | H2: Open | I2: 500000000 | J2: 3000000000
A3: BR002 | B3: Hlaing Branch | C3: City | D3: Yangon | E3: Yangon Region | F3: Rented | G3: 40330 | H3: Open | I3: 100000000 | J3: 800000000
A4: BR003 | B4: Thingangyun Branch | C4: City | D4: Yangon | E4: Yangon Region | F4: Owned | G4: 40969 | H4: Open | I4: 100000000 | J4: 800000000
A5: BR004 | B5: Chanayethazan Branch | C5: City | D5: Mandalay | E5: Mandalay Region | F5: Owned | G5: 40756 | H5: Open | I5: 100000000 | J5: 800000000
A6: BR005 | B6: Aungmyaythazan Branch | C6: City | D6: Mandalay | E6: Mandalay Region | F6: Rented | G6: 41671 | H6: Open | I6: 100000000 | J6: 800000000
A7: BR006 | B7: Zabuthiri Branch | C7: City | D7: Naypyitaw | E7: Naypyitaw Union Territory | F7: Rented | G7: 41518 | H7: Open | I7: 100000000 | J7: 800000000
A8: BR007 | B8: Mawlamyine Branch | C8: City | D8: Mawlamyine | E8: Mon State | F8: Rented | G8: 42005 | H8: Open | I8: 100000000 | J8: 800000000
A9: BR008 | B9: Taunggyi Branch | C9: City | D9: Taunggyi | E9: Shan State | F9: Owned | G9: 42491 | H9: Open | I9: 100000000 | J9: 800000000
A10: BR009 | B10: Pyin Oo Lwin Branch | C10: Town | D10: Pyin Oo Lwin | E10: Mandalay Region | F10: Rented | G10: 42917 | H10: Open | I10: 40000000 | J10: 300000000
A11: BR010 | B11: Kyaukse Branch | C11: Town | D11: Kyaukse | E11: Mandalay Region | F11: Rented | G11: 43160 | H11: Open | I11: 40000000 | J11: 300000000
A12: BR011 | B12: Meiktila Branch | C12: Town | D12: Meiktila | E12: Mandalay Region | F12: Owned | G12: 43040 | H12: Open | I12: 40000000 | J12: 300000000
A13: BR012 | B13: Monywa Branch | C13: Town | D13: Monywa | E13: Sagaing Region | F13: Rented | G13: 43344 | H13: Open | I13: 40000000 | J13: 300000000
... A16: BR015 | B16: Nyaung-U Branch | C16: Town | D16: Nyaung-U | E16: Mandalay Region | F16: Rented | G16: 43831 | H16: Open | I16: 40000000 | J16: 300000000

Sheet Customers
A1: CustomerID | B1: Name | C1: CustomerType | D1: Phone | E1: Address | F1: HomeBranchID | G1: KYCLevel | H1: TaxExempt | I1: JoinDate | J1: Status
A2: C000001 | B2: Thet Htet Naing | C2: Individual | D2: 09363384229 | E2: No.158, 43th Street, Bago | F2: BR014 | G2: 1 | H2: No | I2: 43131 | J2: Active
A3: C000002 | B3: Eastern Garment Co., Ltd. | C3: Business | D3: 09423549521 | E3: No.213, 56th Street, Yangon | F3: BR002 | G3: 3 | H3: No | I3: 43157 | J3: Active
A4: C000003 | B4: Thet Lin Htay | C4: Individual | D4: 09352221721 | E4: No.68, 23th Street, Naypyitaw | F4: BR006 | G4: 1 | H4: No | I4: 43160 | J4: Active
A5: C000004 | B5: Lin Moe Soe | C5: Individual | D5: 09573011995 | E5: No.48, 35th Street, Yangon | F5: BR002 | G5: 1 | H5: No | I5: 43176 | J5: Active
A6: C000005 | B6: Shwe Moe Myint | C6: Individual | D6: 09695977814 | E6: No.84, 78th Street, Naypyitaw | F6: BR006 | G6: 1 | H6: No | I6: 43189 | J6: Active
A7: C000006 | B7: Eastern Logistics Co., Ltd. | C7: Business | D7: 09511046076 | E7: No.156, 87th Street, Mandalay | F7: BR004 | G7: 3 | H7: No | I7: 43235 | J7: Active
A8: C000007 | B8: Mya Thant Thein | C8: Individual | D8: 09287283525 | E8: No.63, 87th Street, Yangon | F8: BR001 | G8: 1 | H8: No | I8: 43258 | J8: Active
A9: C000008 | B9: Nilar Hlaing Win | C9: Individual | D9: 09280417312 | E9: No.22, 79th Street, Yangon | F9: BR001 | G9: 1 | H9: No | I9: 43265 | J9: Active
A10: C000009 | B10: Thandar Thu Swe | C10: Individual | D10: 09597112124 | E10: No.199, 78th Street, Mandalay | F10: BR005 | G10: 1 | H10: No | I10: 43284 | J10: Active
A11: C000010 | B11: Aung Khant Lwin | C11: Individual | D11: 09753693898 | E11: No.218, 49th Street, Yangon | F11: BR002 | G11: 3 | H11: No | I11: 43296 | J11: Active
A12: C000011 | B12: Min Pyae Swe | C12: Individual | D12: 09740170522 | E12: No.141, 44th Street, Mawlamyine | F12: BR007 | G12: 1 | H12: No | I12: 43308 | J12: Active
A13: C000012 | B13: Aye Mon Han | C13: Individual | D13: 09275869564 | E13: No.221, 80th Street, Yangon | F13: BR003 | G13: 1 | H13: No | I13: 43319 | J13: Active
... A321: C000320 | B321: Yadanar Thant Thein | C321: Individual | D321: 09293181323 | E321: No.127, 67th Street, Kyaukse | F321: BR010 | G321: 1 | H321: No | I321: 46264 | J321: Active

Sheet Products
A1: ProductCode | B1: Name | C1: Type | D1: Currency | E1: MinBalance | F1: MinOpening | G1: MaintenanceFeeCode | H1: IsActive
A2: SAV01 | B2: Regular Savings | C2: Savings | D2: MMK | E2: 10000 | F2: 10000 | H2: Yes
A3: SAV02 | B3: Premium Savings | C3: Savings | D3: MMK | E3: 5000000 | F3: 5000000 | H3: Yes
A4: CUR01 | B4: Current Account | C4: Current | D4: MMK | E4: 100000 | F4: 100000 | G4: MAINT_CUR_LOW | H4: Yes
A5: CUR02 | B5: Business Current | C5: Current | D5: MMK | E5: 1000000 | F5: 1000000 | G5: MAINT_CUR_LOW | H5: Yes
A6: FD01 | B6: Fixed Deposit | C6: Fixed | D6: MMK | E6: 0 | F6: 1000000 | H6: Yes

Sheet RateTiers
A1: RateID | B1: ProductCode | C1: TermMonths | D1: FromAmount | E1: ToAmount | F1: AnnualRate | G1: EffectiveFrom
A2: R0001 | B2: SAV01 | C2: 0 | D2: 0 | E2: 1000000 | F2: 0.02 | G2: 45292
A3: R0002 | B3: SAV01 | C3: 0 | D3: 1000000 | E3: 10000000 | F3: 0.025 | G3: 45292
A4: R0003 | B4: SAV01 | C4: 0 | D4: 10000000 | F4: 0.03 | G4: 45292
A5: R0004 | B5: SAV02 | C5: 0 | D5: 0 | E5: 50000000 | F5: 0.035 | G5: 45292
A6: R0005 | B6: SAV02 | C6: 0 | D6: 50000000 | F6: 0.04 | G6: 45292
A7: R0006 | B7: CUR01 | C7: 0 | D7: 0 | F7: 0 | G7: 45292
A8: R0007 | B8: CUR02 | C8: 0 | D8: 0 | E8: 10000000 | F8: 0 | G8: 45292
A9: R0008 | B9: CUR02 | C9: 0 | D9: 10000000 | F9: 0.003 | G9: 45292
A10: R0009 | B10: FD01 | C10: 3 | D10: 1000000 | E10: 50000000 | F10: 0.05 | G10: 45292
A11: R0010 | B11: FD01 | C11: 3 | D11: 50000000 | F11: 0.055 | G11: 45292
A12: R0011 | B12: FD01 | C12: 6 | D12: 1000000 | E12: 50000000 | F12: 0.06 | G12: 45292
A13: R0012 | B13: FD01 | C13: 6 | D13: 50000000 | F13: 0.065 | G13: 45292
A14: R0013 | B14: FD01 | C14: 12 | D14: 1000000 | E14: 50000000 | F14: 0.075 | G14: 45292
A15: R0014 | B15: FD01 | C15: 12 | D15: 50000000 | F15: 0.08 | G15: 45292
A16: R0015 | B16: FD01 | C16: 24 | D16: 1000000 | E16: 50000000 | F16: 0.08 | G16: 45292
A17: R0016 | B17: FD01 | C17: 24 | D17: 50000000 | F17: 0.085 | G17: 45292
A18: R0017 | B18: SAV01 | C18: 0 | D18: 0 | E18: 1000000 | F18: 0.025 | G18: 45658
A19: R0018 | B19: SAV01 | C19: 0 | D19: 1000000 | E19: 10000000 | F19: 0.03 | G19: 45658
A20: R0019 | B20: SAV01 | C20: 0 | D20: 10000000 | F20: 0.035 | G20: 45658
A21: R0020 | B21: SAV02 | C21: 0 | D21: 0 | E21: 50000000 | F21: 0.04 | G21: 45658
A22: R0021 | B22: SAV02 | C22: 0 | D22: 50000000 | F22: 0.045 | G22: 45658
A23: R0022 | B23: CUR01 | C23: 0 | D23: 0 | F23: 0 | G23: 45658
A24: R0023 | B24: CUR02 | C24: 0 | D24: 0 | E24: 10000000 | F24: 0 | G24: 45658
A25: R0024 | B25: CUR02 | C25: 0 | D25: 10000000 | F25: 0.004 | G25: 45658
A26: R0025 | B26: FD01 | C26: 3 | D26: 1000000 | E26: 50000000 | F26: 0.055 | G26: 45658
A27: R0026 | B27: FD01 | C27: 3 | D27: 50000000 | F27: 0.06 | G27: 45658
A28: R0027 | B28: FD01 | C28: 6 | D28: 1000000 | E28: 50000000 | F28: 0.065 | G28: 45658
A29: R0028 | B29: FD01 | C29: 6 | D29: 50000000 | F29: 0.07 | G29: 45658
A30: R0029 | B30: FD01 | C30: 12 | D30: 1000000 | E30: 50000000 | F30: 0.08 | G30: 45658
A31: R0030 | B31: FD01 | C31: 12 | D31: 50000000 | F31: 0.085 | G31: 45658
A32: R0031 | B32: FD01 | C32: 24 | D32: 1000000 | E32: 50000000 | F32: 0.085 | G32: 45658
A33: R0032 | B33: FD01 | C33: 24 | D33: 50000000 | F33: 0.09 | G33: 45658
A34: R0033 | B34: SAV01 | C34: 0 | D34: 0 | E34: 1000000 | F34: 0.03 | G34: 46023
A35: R0034 | B35: SAV01 | C35: 0 | D35: 1000000 | E35: 10000000 | F35: 0.035 | G35: 46023
A36: R0035 | B36: SAV01 | C36: 0 | D36: 10000000 | F36: 0.04 | G36: 46023
A37: R0036 | B37: SAV02 | C37: 0 | D37: 0 | E37: 50000000 | F37: 0.045 | G37: 46023
A38: R0037 | B38: SAV02 | C38: 0 | D38: 50000000 | F38: 0.05 | G38: 46023
A39: R0038 | B39: CUR01 | C39: 0 | D39: 0 | F39: 0 | G39: 46023
A40: R0039 | B40: CUR02 | C40: 0 | D40: 0 | E40: 10000000 | F40: 0 | G40: 46023
...

Sheet Fees
A1: FeeCode | B1: Name | C1: Method | D1: FlatAmount | E1: Rate | F1: MinFee | G1: MaxFee | H1: Currency | I1: IncomeGL
A2: CROSS_BRANCH_WD | B2: Cash withdrawal at another branch | C2: Percent | D2: 0 | E2: 0.001 | F2: 500 | G2: 20000 | H2: MMK | I2: 4100
A3: TRANSFER_SAME | B3: Transfer within the same branch | C3: Flat | D3: 0 | E3: 0 | F3: 0 | G3: 0 | H3: MMK | I3: 4100
A4: TRANSFER_BRANCH | B4: Transfer to another branch | C4: Percent | D4: 0 | E4: 0.0005 | F4: 300 | G4: 10000 | H4: MMK | I4: 4100
A5: INTERBANK_OUT | B5: Transfer to another bank (simulated) | C5: Percent | D5: 0 | E5: 0.001 | F5: 1000 | G5: 25000 | H5: MMK | I5: 4100
A6: INTERBANK_IN | B6: Transfer from another bank (simulated) | C6: Flat | D6: 0 | E6: 0 | F6: 0 | G6: 0 | H6: MMK | I6: 4100
A7: MAINT_CUR_LOW | B7: Monthly fee, current account below minimum balance | C7: Flat | D7: 3000 | E7: 0 | F7: 0 | G7: 0 | H7: MMK | I7: 4100
A8: FD_EARLY_BREAK | B8: Early break of fixed deposit | C8: Percent | D8: 0 | E8: 0.005 | F8: 0 | G8: 0 | H8: MMK | I8: 4100

Sheet OtherBanks
A1: BankCode | B1: Name | C1: SettleDays | D1: FailRate | E1: ReturnRate
A2: OB01 | B2: Sunrise Commercial Bank (simulated) | C2: 1 | D2: 0.03 | E2: 0.01
A3: OB02 | B3: Golden River Bank (simulated) | C3: 2 | D3: 0.04 | E3: 0.01
A4: OB03 | B4: Delta Savings Bank (simulated) | C4: 2 | D4: 0.05 | E4: 0.02
A5: OB04 | B5: Capital Trust Bank (simulated) | C5: 1 | D5: 0.02 | E5: 0.01

Sheet Chart
A1: GLCode | B1: Name | C1: Type | D1: NormalSide | E1: Stage | F1: IsActive
A2: 1000 | B2: Cash in vault | C2: Asset | D2: Debit | E2: 1 | F2: Yes
A3: 1100 | B3: Treasury and settlement balances | C3: Asset | D3: Debit | E3: 1 | F3: Yes
A4: 1300 | B4: Loans receivable | C4: Asset | D4: Debit | E4: 3 | F4: No
A5: 1310 | B5: Interest receivable | C5: Asset | D5: Debit | E5: 3 | F5: No
A6: 1400 | B6: Repossessed assets held for sale | C6: Asset | D6: Debit | E6: 4 | F6: No
A7: 1500 | B7: Premises and equipment, cost | C7: Asset | D7: Debit | E7: 2 | F7: No
A8: 1510 | B8: Accumulated depreciation | C8: Asset | D8: Credit | E8: 2 | F8: No
A9: 1600 | B9: Business investments | C9: Asset | D9: Debit | E9: 7 | F9: No
A10: 1700 | B10: Foreign currency holdings | C10: Asset | D10: Debit | E10: 6 | F10: No
A11: 1800 | B11: Prepaid expenses | C11: Asset | D11: Debit | E11: 2 | F11: No
A12: 1900 | B12: Inter-branch clearing | C12: Asset | D12: Debit | E12: 1 | F12: Yes
A13: 2000 | B13: Savings deposits | C13: Liability | D13: Credit | E13: 1 | F13: Yes
... A51: 5500 | B51: Other expenses | C51: Expense | D51: Debit | E51: 2 | F51: No

Sheet Accounts
A1: AccountNo | B1: CustomerID | C1: BranchID | D1: ProductCode | E1: Currency | F1: Status | G1: OpenDate | H1: TermMonths | I1: MaturityDate | J1: LockedRate | K1: PayoutAccountNo | L1: Balance | M1: AccruedInterest | N1: LastAccrualDate | O1: LastActivityDate | P1: ClosedDate
A2: 0010000009 | B2: C000007 | C2: BR001 | D2: SAV01 | E2: MMK | F2: Active | G2: 43503 | L2: 3664780 | M2: 3649.3593 | N2: 46307 | O2: 46301
A3: 0010000010 | B3: C000007 | C3: BR001 | D3: CUR01 | E3: MMK | F3: Dormant | G3: 44223 | L3: 1167172 | M3: 0 | N3: 46307 | O3: 45870
A4: 0010000011 | B4: C000008 | C4: BR001 | D4: SAV01 | E4: MMK | F4: Active | G4: 45199 | L4: 3940665 | M4: 4534.464 | N4: 46307 | O4: 46250
A5: 0010000024 | B5: C000017 | C5: BR001 | D5: CUR02 | E5: MMK | F5: Active | G5: 45515 | L5: 25028259 | M5: 4114.2348 | N5: 46307 | O5: 46236
A6: 0010000025 | B6: C000017 | C6: BR001 | D6: SAV01 | E6: MMK | F6: Active | G6: 45955 | L6: 277992 | M6: 808.6846 | N6: 46307 | O6: 46304
A7: 0010000031 | B7: C000023 | C7: BR001 | D7: SAV02 | E7: MMK | F7: Active | G7: 43756 | L7: 5519618 | M7: 7922.6207 | N7: 46307 | O7: 46301
A8: 0010000036 | B8: C000028 | C8: BR001 | D8: SAV01 | E8: MMK | F8: Active | G8: 43982 | L8: 5890348 | M8: 6578.5535 | N8: 46307 | O8: 46307
A9: 0010000076 | B9: C000059 | C9: BR001 | D9: SAV01 | E9: MMK | F9: Active | G9: 46141 | L9: 4373333 | M9: 4832.6903 | N9: 46307 | O9: 46305
A10: 0010000092 | B10: C000072 | C10: BR001 | D10: CUR02 | E10: MMK | F10: Active | G10: 46281 | L10: 17801658 | M10: 2949.7281 | N10: 46307 | O10: 46301
A11: 0010000120 | B11: C000096 | C11: BR001 | D11: SAV01 | E11: MMK | F11: Active | G11: 45277 | L11: 2494569 | M11: 2749.124 | N11: 46307 | O11: 46306
A12: 0010000130 | B12: C000104 | C12: BR001 | D12: SAV01 | E12: MMK | F12: Active | G12: 45828 | L12: 775946 | M12: 815.4856 | N12: 46307 | O12: 46300
A13: 0010000131 | B13: C000104 | C13: BR001 | D13: CUR01 | E13: MMK | F13: Active | G13: 46056 | L13: 3927282 | M13: 0 | N13: 46307 | O13: 46296
... A25: 0010000367 | B25: C000293 | C25: BR001 | D25: CUR01 | E25: MMK | F25: Active | G25: 46284 | L25: 393034 | M25: 0 | N25: 46307 | O25: 46300
A26: 0010000405 | B26: C000248 | C26: BR001 | D26: FD01 | E26: MMK | F26: Active | G26: 46122 | H26: 12 | I26: 46487 | J26: 0.085 | K26: 0010000312 | L26: 14975162 | M26: 648650.17 | N26: 46307 | O26: 46122
A27: 0010000422 | B27: C000023 | C27: BR001 | D27: FD01 | E27: MMK | F27: Active | G27: 46012 | H27: 24 | I27: 46742 | J27: 0.085 | K27: 0010000031 | L27: 6675443 | M27: 460148.34 | N27: 46307 | O27: 46012
A28: 0010000445 | B28: C000007 | C28: BR001 | D28: SAV01 | E28: MMK | F28: Active | G28: 46302 | L28: 126516 | M28: 119.8508 | N28: 46307 | O28: 46306
A29: 0020000002 | B29: C000002 | C29: BR002 | D29: CUR02 | E29: MMK | F29: Active | G29: 43570 | L29: 47796356 | M29: 7900.0332 | N29: 46307 | O29: 46306
A30: 0020000005 | B30: C000004 | C30: BR002 | D30: SAV01 | E30: MMK | F30: Active | G30: 44354 | L30: 377638 | M30: 483.6583 | N30: 46307 | O30: 46306
A31: 0020000013 | B31: C000010 | C31: BR002 | D31: SAV01 | E31: MMK | F31: Active | G31: 45440 | L31: 2647378 | M31: 2041.0314 | N31: 46307 | O31: 46301
A32: 0020000030 | B32: C000022 | C32: BR002 | D32: SAV01 | E32: MMK | F32: Active | G32: 46053 | L32: 1010809 | M32: 744.0482 | N32: 46307 | O32: 46303
A33: 0020000034 | B33: C000026 | C33: BR002 | D33: SAV01 | E33: MMK | F33: Active | G33: 45754 | L33: 126908 | M33: 240.4752 | N33: 46307 | O33: 46304
A34: 0020000041 | B34: C000033 | C34: BR002 | D34: SAV01 | E34: MMK | F34: Active | G34: 44032 | L34: 8119875 | M34: 9097.7828 | N34: 46307 | O34: 46300
A35: 0020000069 | B35: C000054 | C35: BR002 | D35: SAV01 | E35: MMK | F35: Active | G35: 45615 | L35: 5571095 | M35: 5821.9031 | N35: 46307 | O35: 46307
A36: 0020000070 | B36: C000054 | C36: BR002 | D36: CUR01 | E36: MMK | F36: Active | G36: 45468 | L36: 776704 | M36: 0 | N36: 46307 | O36: 46272
A37: 0020000085 | B37: C000067 | C37: BR002 | D37: CUR02 | E37: MMK | F37: Active | G37: 44425 | L37: 41363081 | M37: 6761.1729 | N37: 46307 | O37: 46307
A38: 0020000086 | B38: C000067 | C38: BR002 | D38: SAV01 | E38: MMK | F38: Active | G38: 45676 | L38: 8231473 | M38: 5346.03 | N38: 46307 | O38: 46304
A39: 0020000096 | B39: C000075 | C39: BR002 | D39: SAV02 | E39: MMK | F39: Active | G39: 45989 | L39: 12065802 | M39: 18042.599 | N39: 46307 | O39: 46300
... A60: 0020000357 | B60: C000286 | C60: BR002 | D60: SAV01 | E60: MMK | F60: Active | G60: 46188 | L60: 2285718 | M60: 2630.1408 | N60: 46307 | O60: 46287
A61: 0020000423 | B61: C000263 | C61: BR002 | D61: FD01 | E61: MMK | F61: Active | G61: 46287 | H61: 3 | I61: 46378 | J61: 0.06 | K61: 0020000330 | L61: 5664075 | M61: 19552.697 | N61: 46307 | O61: 46287
A62: 0030000015 | B62: C000012 | C62: BR003 | D62: SAV01 | E62: MMK | F62: Active | G62: 44567 | L62: 11294647 | M62: 13707.504 | N62: 46307 | O62: 46307
A63: 0030000016 | B63: C000012 | C63: BR003 | D63: CUR01 | E63: MMK | F63: Active | G63: 44532 | L63: 5510281 | M63: 0 | N63: 46307 | O63: 46306
A64: 0030000033 | B64: C000025 | C64: BR003 | D64: SAV01 | E64: MMK | F64: Active | G64: 45868 | L64: 1116752 | M64: 1246.3775 | N64: 46307 | O64: 46299
A65: 0030000045 | B65: C000037 | C65: BR003 | D65: CUR02 | E65: MMK | F65: Active | G65: 46287 | L65: 61601285 | M65: 10110.556 | N65: 46307 | O65: 46305
A66: 0030000046 | B66: C000037 | C66: BR003 | D66: SAV01 | E66: MMK | F66: Active | G66: 44700 | L66: 33603338 | M66: 40561.694 | N66: 46307 | O66: 46306
A67: 0030000047 | B67: C000038 | C67: BR003 | D67: SAV01 | E67: MMK | F67: Active | G67: 44684 | L67: 912694 | M67: 1124.8236 | N67: 46307 | O67: 46304
A68: 0030000057 | B68: C000046 | C68: BR003 | D68: CUR02 | E68: MMK | F68: Active | G68: 46287 | L68: 122125089 | M68: 20075.357 | N68: 46307 | O68: 46287
A69: 0030000065 | B69: C000052 | C69: BR003 | D69: SAV01 | E69: MMK | F69: Active | G69: 45190 | L69: 1953721 | M69: 2166.4057 | N69: 46307 | O69: 46301
A70: 0030000066 | B70: C000052 | C70: BR003 | D70: CUR01 | E70: MMK | F70: Active | G70: 45004 | L70: 623935 | M70: 0 | N70: 46307 | O70: 46307
A71: 0030000072 | B71: C000056 | C71: BR003 | D71: CUR02 | E71: MMK | F71: Active | G71: 44581 | L71: 14217637 | M71: 584.2866 | N71: 46307 | O71: 46305
...

Sheet Transactions
A1: TxnID | B1: GroupID | C1: TxnDate | D1: AccountNo | E1: TxnType | F1: Direction | G1: Amount | H1: BalanceAfter | I1: CounterAccountNo | J1: BranchID | K1: Description | L1: Reference | M1: JournalID | N1: Status | O1: CreatedBy | P1: ApprovedBy
A2: TX20260930-00001 | B2: G20260930-00001 | C2: 46295 | D2: 0010000009 | E2: Opening | F2: Credit | G2: 1602465 | H2: 1602465 | J2: BR001 | K2: Opening balance | M2: J00000017 | N2: Posted | O2: U001
A3: TX20260930-00002 | B3: G20260930-00001 | C3: 46295 | D3: 0010000010 | E3: Opening | F3: Credit | G3: 1167172 | H3: 1167172 | J3: BR001 | K3: Opening balance | M3: J00000017 | N3: Posted | O3: U001
A4: TX20260930-00003 | B4: G20260930-00001 | C4: 46295 | D4: 0010000011 | E4: Opening | F4: Credit | G4: 3940665 | H4: 3940665 | J4: BR001 | K4: Opening balance | M4: J00000017 | N4: Posted | O4: U001
A5: TX20260930-00004 | B5: G20260930-00001 | C5: 46295 | D5: 0010000024 | E5: Opening | F5: Credit | G5: 25028259 | H5: 25028259 | J5: BR001 | K5: Opening balance | M5: J00000017 | N5: Posted | O5: U001
A6: TX20260930-00005 | B6: G20260930-00001 | C6: 46295 | D6: 0010000025 | E6: Opening | F6: Credit | G6: 1712602 | H6: 1712602 | J6: BR001 | K6: Opening balance | M6: J00000017 | N6: Posted | O6: U001
A7: TX20260930-00006 | B7: G20260930-00001 | C7: 46295 | D7: 0010000031 | E7: Opening | F7: Credit | G7: 5000000 | H7: 5000000 | J7: BR001 | K7: Opening balance | M7: J00000017 | N7: Posted | O7: U001
A8: TX20260930-00007 | B8: G20260930-00001 | C8: 46295 | D8: 0010000036 | E8: Opening | F8: Credit | G8: 5612344 | H8: 5612344 | J8: BR001 | K8: Opening balance | M8: J00000017 | N8: Posted | O8: U001
A9: TX20260930-00008 | B9: G20260930-00001 | C9: 46295 | D9: 0010000076 | E9: Opening | F9: Credit | G9: 4688765 | H9: 4688765 | J9: BR001 | K9: Opening balance | M9: J00000017 | N9: Posted | O9: U001
A10: TX20260930-00009 | B10: G20260930-00001 | C10: 46295 | D10: 0010000092 | E10: Opening | F10: Credit | G10: 18143711 | H10: 18143711 | J10: BR001 | K10: Opening balance | M10: J00000017 | N10: Posted | O10: U001
A11: TX20260930-00010 | B11: G20260930-00001 | C11: 46295 | D11: 0010000120 | E11: Opening | F11: Credit | G11: 2387847 | H11: 2387847 | J11: BR001 | K11: Opening balance | M11: J00000017 | N11: Posted | O11: U001
A12: TX20260930-00011 | B12: G20260930-00001 | C12: 46295 | D12: 0010000130 | E12: Opening | F12: Credit | G12: 928543 | H12: 928543 | J12: BR001 | K12: Opening balance | M12: J00000017 | N12: Posted | O12: U001
A13: TX20260930-00012 | B13: G20260930-00001 | C13: 46295 | D13: 0010000131 | E13: Opening | F13: Credit | G13: 6778299 | H13: 6778299 | J13: BR001 | K13: Opening balance | M13: J00000017 | N13: Posted | O13: U001
... A463: TX20261001-00026 | B463: G20261001-00026 | C463: 46296 | D463: 0040000358 | E463: Withdrawal | F463: Debit | G463: 295764 | H463: 28572417 | J463: BR005 | K463: Cash withdrawal | M463: J00000058 | N463: Posted | O463: U017
A464: TX20261001-00027 | B464: G20261001-00026 | C464: 46296 | D464: 0040000358 | E464: Fee | F464: Debit | G464: 500 | H464: 28571917 | J464: BR005 | K464: Cross-branch cash withdrawal fee | L464: CROSS_BRANCH_WD | M464: J00000058 | N464: Posted | O464: U017
A465: TX20261001-00028 | B465: G20261001-00027 | C465: 46296 | D465: 0050000089 | E465: Withdrawal | F465: Debit | G465: 266313 | H465: 187543 | J465: BR005 | K465: Cash withdrawal | M465: J00000059 | N465: Posted | O465: U018
A466: TX20261001-00029 | B466: G20261001-00028 | C466: 46296 | D466: 0070000249 | E466: Withdrawal | F466: Debit | G466: 597948 | H466: 2418632 | J466: BR007 | K466: Cash withdrawal | M466: J00000060 | N466: Posted | O466: U024
A467: TX20261001-00030 | B467: G20261001-00029 | C467: 46296 | D467: 0030000107 | E467: Withdrawal | F467: Debit | G467: 211968 | H467: 2044111 | J467: BR003 | K467: Cash withdrawal | M467: J00000061 | N467: Posted | O467: U011
A468: TX20261001-00031 | B468: G20261001-00030 | C468: 46296 | D468: 0130000361 | E468: Withdrawal | F468: Debit | G468: 1805446 | H468: 7439744 | J468: BR013 | K468: Cash withdrawal | M468: J00000062 | N468: Posted | O468: U041
A469: TX20261001-00032 | B469: G20261001-00031 | C469: 46296 | D469: 0090000021 | E469: Withdrawal | F469: Debit | G469: 113728 | H469: 14316854 | J469: BR009 | K469: Cash withdrawal | M469: J00000063 | N469: Posted | O469: U029
A470: TX20261001-00033 | B470: G20261001-00032 | C470: 46296 | D470: 0010000131 | E470: Withdrawal | F470: Debit | G470: 2851017 | H470: 3927282 | J470: BR001 | K470: Cash withdrawal | M470: J00000064 | N470: Posted | O470: U005
A471: TX20261001-00034 | B471: G20261001-00033 | C471: 46296 | D471: 0060000369 | E471: Withdrawal | F471: Debit | G471: 622753 | H471: 425170 | J471: BR006 | K471: Cash withdrawal | M471: J00000065 | N471: Posted | O471: U020
A472: TX20261001-00035 | B472: G20261001-00034 | C472: 46296 | D472: 0040000168 | E472: Withdrawal | F472: Debit | G472: 2624751 | H472: 5975132 | J472: BR004 | K472: Cash withdrawal | M472: J00000066 | N472: Posted | O472: U014
A473: TX20261001-00036 | B473: G20261001-00035 | C473: 46296 | D473: 0060000095 | E473: Withdrawal | F473: Debit | G473: 532362 | H473: 364908 | J473: BR006 | K473: Cash withdrawal | M473: J00000067 | N473: Posted | O473: U020
A474: TX20261001-00037 | B474: G20261001-00036 | C474: 46296 | D474: 0060000365 | E474: Withdrawal | F474: Debit | G474: 401172 | H474: 788014 | J474: BR006 | K474: Cash withdrawal | M474: J00000068 | N474: Posted | O474: U020
A475: TX20261001-00038 | B475: G20261001-00037 | C475: 46296 | D475: 0090000195 | E475: TransferOut | F475: Debit | G475: 240695 | H475: 1403290 | I475: 0070000173 | J475: BR009 | K475: Transfer | M475: J00000069 | N475: Posted | O475: U030
A476: TX20261001-00039 | B476: G20261001-00037 | C476: 46296 | D476: 0090000195 | E476: Fee | F476: Debit | G476: 300 | H476: 1402990 | J476: BR009 | K476: Branch transfer fee | L476: TRANSFER_BRANCH | M476: J00000069 | N476: Posted | O476: U030
A477: TX20261001-00040 | B477: G20261001-00037 | C477: 46296 | D477: 0070000173 | E477: TransferIn | F477: Credit | G477: 240695 | H477: 7258206 | I477: 0090000195 | J477: BR009 | K477: Transfer | M477: J00000069 | N477: Posted | O477: U030
A478: TX20261001-00041 | B478: G20261001-00038 | C478: 46296 | D478: 0040000207 | E478: TransferOut | F478: Debit | G478: 75480 | H478: 3758522 | I478: 0060000393 | J478: BR004 | K478: Transfer | M478: J00000070 | N478: Posted | O478: U015
A479: TX20261001-00042 | B479: G20261001-00038 | C479: 46296 | D479: 0040000207 | E479: Fee | F479: Debit | G479: 300 | H479: 3758222 | J479: BR004 | K479: Branch transfer fee | L479: TRANSFER_BRANCH | M479: J00000070 | N479: Posted | O479: U015
A480: TX20261001-00043 | B480: G20261001-00038 | C480: 46296 | D480: 0060000393 | E480: TransferIn | F480: Credit | G480: 75480 | H480: 1200355 | I480: 0040000207 | J480: BR004 | K480: Transfer | M480: J00000070 | N480: Posted | O480: U015
A481: TX20261001-00044 | B481: G20261001-00039 | C481: 46296 | D481: 0080000162 | E481: TransferOut | F481: Debit | G481: 689179 | H481: 5887611 | I481: 0090000332 | J481: BR008 | K481: Transfer | M481: J00000071 | N481: Posted | O481: U026
A482: TX20261001-00045 | B482: G20261001-00039 | C482: 46296 | D482: 0080000162 | E482: Fee | F482: Debit | G482: 345 | H482: 5887266 | J482: BR008 | K482: Branch transfer fee | L482: TRANSFER_BRANCH | M482: J00000071 | N482: Posted | O482: U026
A483: TX20261001-00046 | B483: G20261001-00039 | C483: 46296 | D483: 0090000332 | E483: TransferIn | F483: Credit | G483: 689179 | H483: 1734043 | I483: 0080000162 | J483: BR008 | K483: Transfer | M483: J00000071 | N483: Posted | O483: U026
A484: TX20261001-00047 | B484: G20261001-00040 | C484: 46296 | D484: 0140000290 | E484: TransferOut | F484: Debit | G484: 321561 | H484: 35397004 | I484: 0070000333 | J484: BR014 | K484: Transfer | M484: J00000072 | N484: Posted | O484: U044
A485: TX20261001-00048 | B485: G20261001-00040 | C485: 46296 | D485: 0140000290 | E485: Fee | F485: Debit | G485: 300 | H485: 35396704 | J485: BR014 | K485: Branch transfer fee | L485: TRANSFER_BRANCH | M485: J00000072 | N485: Posted | O485: U044
A486: TX20261001-00049 | B486: G20261001-00040 | C486: 46296 | D486: 0070000333 | E486: TransferIn | F486: Credit | G486: 321561 | H486: 1841880 | I486: 0140000290 | J486: BR014 | K486: Transfer | M486: J00000072 | N486: Posted | O486: U044
A487: TX20261001-00050 | B487: G20261001-00041 | C487: 46296 | D487: 0030000254 | E487: TransferOut | F487: Debit | G487: 167428 | H487: 2196815 | I487: 0030000390 | J487: BR003 | K487: Transfer | M487: J00000073 | N487: Posted | O487: U011
A488: TX20261001-00051 | B488: G20261001-00041 | C488: 46296 | D488: 0030000390 | E488: TransferIn | F488: Credit | G488: 167428 | H488: 3746039 | I488: 0030000254 | J488: BR003 | K488: Transfer | M488: J00000073 | N488: Posted | O488: U011
A489: TX20261001-00052 | B489: G20261001-00042 | C489: 46296 | D489: 0150000303 | E489: TransferOut | F489: Debit | G489: 441790 | H489: 1441790 | I489: 0030000245 | J489: BR015 | K489: Transfer | M489: J00000074 | N489: Posted | O489: U047
...

Sheet InterbankTransfers
A1: TransferID | B1: Direction | C1: AccountNo | D1: OtherBankCode | E1: OtherBankAccount | F1: Amount | G1: Fee | H1: SubmittedDate | I1: ExpectedSettleDate | J1: Status | K1: StatusDate | L1: Reason | M1: SubmitJournalID | N1: SettleJournalID | O1: ReturnJournalID
A2: IB000001 | B2: Out | C2: 0030000375 | D2: OB01 | E2: 1581409834 | F2: 156047 | G2: 1000 | H2: 46296 | I2: 46297 | J2: Returned | K2: 46304 | L2: Returned after settlement (simulated) | M2: J00000079 | N2: J00000141 | O2: J00000536
A3: IB000002 | B3: In | C3: 0040000168 | D3: OB03 | E3: 6898735050 | F3: 624140 | G3: 0 | H3: 46296 | I3: 46296 | J3: Settled | K3: 46296 | M3: J00000080
A4: IB000003 | B4: Out | C4: 0140000326 | D4: OB02 | E4: 6152481848 | F4: 332157 | G4: 1000 | H4: 46297 | I4: 46299 | J4: Settled | K4: 46299 | M4: J00000137 | N4: J00000244
A5: IB000004 | B5: Out | C5: 0070000250 | D5: OB04 | E5: 5018109944 | F5: 388239 | G5: 1000 | H5: 46297 | I5: 46298 | J5: Settled | K5: 46298 | M5: J00000138 | N5: J00000192
A6: IB000005 | B6: Out | C6: 0020000350 | D6: OB03 | E6: 6065832573 | F6: 373780 | G6: 1000 | H6: 46297 | I6: 46299 | J6: Settled | K6: 46299 | M6: J00000139 | N6: J00000245
A7: IB000006 | B7: In | C7: 0030000254 | D7: OB03 | E7: 2685210444 | F7: 226589 | G7: 0 | H7: 46297 | I7: 46297 | J7: Settled | K7: 46297 | M7: J00000140
A8: IB000007 | B8: Out | C8: 0060000158 | D8: OB02 | E8: 8940288772 | F8: 232598 | G8: 1000 | H8: 46298 | I8: 46300 | J8: Settled | K8: 46300 | M8: J00000187 | N8: J00000305
A9: IB000008 | B9: Out | C9: 0150000305 | D9: OB03 | E9: 4159874018 | F9: 320905 | G9: 1000 | H9: 46298 | I9: 46300 | J9: Failed | K9: 46300 | L9: Rejected by receiving bank (simulated) | M9: J00000188 | N9: J00000306
A10: IB000009 | B10: In | C10: 0030000015 | D10: OB01 | E10: 6090559763 | F10: 348198 | G10: 0 | H10: 46298 | I10: 46298 | J10: Settled | K10: 46298 | M10: J00000189
A11: IB000010 | B11: In | C11: 0080000373 | D11: OB03 | E11: 6536532038 | F11: 159537 | G11: 0 | H11: 46298 | I11: 46298 | J11: Settled | K11: 46298 | M11: J00000190
A12: IB000011 | B12: Out | C12: 0090000332 | D12: OB01 | E12: 3739797135 | F12: 309898 | G12: 1000 | H12: 46299 | I12: 46300 | J12: Settled | K12: 46300 | M12: J00000240 | N12: J00000307
A13: IB000012 | B13: Out | C13: 0020000276 | D13: OB01 | E13: 8825064736 | F13: 455774 | G13: 1000 | H13: 46299 | I13: 46300 | J13: Settled | K13: 46300 | M13: J00000241 | N13: J00000308
A14: IB000013 | B14: In | C14: 0130000288 | D14: OB04 | E14: 3025221142 | F14: 229992 | G14: 0 | H14: 46299 | I14: 46299 | J14: Settled | K14: 46299 | M14: J00000242
A15: IB000014 | B15: In | C15: 0120000157 | D15: OB04 | E15: 7507708782 | F15: 2314946 | G15: 0 | H15: 46299 | I15: 46299 | J15: Settled | K15: 46299 | M15: J00000243
A16: IB000015 | B16: Out | C16: 0080000294 | D16: OB04 | E16: 1807286349 | F16: 984188 | G16: 1000 | H16: 46300 | I16: 46301 | J16: Settled | K16: 46301 | M16: J00000302 | N16: J00000365
A17: IB000016 | B17: Out | C17: 0020000308 | D17: OB04 | E17: 6275845655 | F17: 441253 | G17: 1000 | H17: 46300 | I17: 46301 | J17: Settled | K17: 46301 | M17: J00000303 | N17: J00000366
A18: IB000017 | B18: In | C18: 0030000180 | D18: OB04 | E18: 1258613570 | F18: 1259598 | G18: 0 | H18: 46300 | I18: 46300 | J18: Settled | K18: 46300 | M18: J00000304
A19: IB000018 | B19: Out | C19: 0140000264 | D19: OB02 | E19: 9431608213 | F19: 223620 | G19: 1000 | H19: 46301 | I19: 46303 | J19: Settled | K19: 46303 | M19: J00000362 | N19: J00000480
A20: IB000019 | B20: Out | C20: 0060000154 | D20: OB02 | E20: 4153152075 | F20: 191077 | G20: 1000 | H20: 46301 | I20: 46303 | J20: Settled | K20: 46303 | M20: J00000363 | N20: J00000481
A21: IB000020 | B21: Out | C21: 0020000136 | D21: OB04 | E21: 4031248076 | F21: 248744 | G21: 1000 | H21: 46301 | I21: 46302 | J21: Settled | K21: 46302 | M21: J00000364 | N21: J00000427
A22: IB000021 | B22: Out | C22: 0050000137 | D22: OB03 | E22: 3536743142 | F22: 246253 | G22: 1000 | H22: 46302 | I22: 46304 | J22: Settled | K22: 46304 | M22: J00000423 | N22: J00000533
A23: IB000022 | B23: Out | C23: 0050000345 | D23: OB02 | E23: 2472670161 | F23: 149635 | G23: 1000 | H23: 46302 | I23: 46304 | J23: Settled | K23: 46304 | M23: J00000424 | N23: J00000534
A24: IB000023 | B24: Out | C24: 0090000307 | D24: OB01 | E24: 6077331293 | F24: 65309 | G24: 1000 | H24: 46302 | I24: 46303 | J24: Settled | K24: 46303 | M24: J00000425 | N24: J00000482
A25: IB000024 | B25: Out | C25: 0020000263 | D25: OB02 | E25: 6447203358 | F25: 173562 | G25: 1000 | H25: 46303 | I25: 46305 | J25: Settled | K25: 46305 | M25: J00000476 | N25: J00000594
A26: IB000025 | B26: Out | C26: 0140000001 | D26: OB01 | E26: 1328214418 | F26: 246034 | G26: 1000 | H26: 46303 | I26: 46304 | J26: Settled | K26: 46304 | M26: J00000477 | N26: J00000535
A27: IB000026 | B27: In | C27: 0120000129 | D27: OB02 | E27: 2712969555 | F27: 965462 | G27: 0 | H27: 46303 | I27: 46303 | J27: Settled | K27: 46303 | M27: J00000478
A28: IB000027 | B28: In | C28: 0040000237 | D28: OB04 | E28: 1012554516 | F28: 2373951 | G28: 0 | H28: 46303 | I28: 46303 | J28: Settled | K28: 46303 | M28: J00000479
A29: IB000028 | B29: Out | C29: 0030000047 | D29: OB01 | E29: 7482342463 | F29: 161440 | G29: 1000 | H29: 46304 | I29: 46305 | J29: Settled | K29: 46305 | M29: J00000530 | N29: J00000595
A30: IB000029 | B30: In | C30: 0100000182 | D30: OB04 | E30: 5873669720 | F30: 329539 | G30: 0 | H30: 46304 | I30: 46304 | J30: Settled | K30: 46304 | M30: J00000531
A31: IB000030 | B31: In | C31: 0050000382 | D31: OB04 | E31: 4679989557 | F31: 1538808 | G31: 0 | H31: 46304 | I31: 46304 | J31: Settled | K31: 46304 | M31: J00000532
A32: IB000031 | B32: Out | C32: 0100000274 | D32: OB01 | E32: 2072382280 | F32: 615566 | G32: 1000 | H32: 46305 | I32: 46306 | J32: Settled | K32: 46306 | M32: J00000589 | N32: J00000646
A33: IB000032 | B33: Out | C33: 0040000225 | D33: OB04 | E33: 8668339000 | F33: 389011 | G33: 1000 | H33: 46305 | I33: 46306 | J33: Settled | K33: 46306 | M33: J00000590 | N33: J00000647
A34: IB000033 | B34: Out | C34: 0110000267 | D34: OB02 | E34: 4556962935 | F34: 222908 | G34: 1000 | H34: 46305 | I34: 46307 | J34: Settled | K34: 46307 | M34: J00000591 | N34: J00000702
A35: IB000034 | B35: In | C35: 0010000076 | D35: OB03 | E35: 3418264401 | F35: 387543 | G35: 0 | H35: 46305 | I35: 46305 | J35: Settled | K35: 46305 | M35: J00000592
A36: IB000035 | B36: Out | C36: 0070000087 | D36: OB02 | E36: 2831809487 | F36: 77411 | G36: 1000 | H36: 46306 | I36: 46308 | J36: Submitted | K36: 46306 | M36: J00000645
A37: IB000036 | B37: Out | C37: 0030000066 | D37: OB02 | E37: 8117199418 | F37: 349956 | G37: 1000 | H37: 46307 | I37: 46309 | J37: Submitted | K37: 46307 | M37: J00000701

Sheet Approvals
A1: ApprovalID | B1: RequestType | C1: AccountNo | D1: CounterAccountNo | E1: Amount | F1: BranchID | G1: Note | H1: RequestedBy | I1: RequestedAt | J1: Status | K1: ApprovedBy | L1: DecidedAt | M1: DecisionNote | N1: TxnGroupID
A2: AP000001 | B2: LargeDeposit | C2: 0100000283 | E2: 27000000 | F2: BR010 | G2: Sample largedeposit | H2: U032 | I2: 46298.411 | J2: Approved | K2: U034 | L2: 46298.456 | N2: G20261003-00050
A3: AP000002 | B3: LargeDeposit | C3: 0060000233 | E3: 15000000 | F3: BR006 | G3: Sample largedeposit | H3: U021 | I3: 46302.381 | J3: Approved | K3: U022 | L3: 46302.419 | N3: G20261007-00060
A4: AP000003 | B4: LargeDeposit | C4: 0040000340 | E4: 17000000 | F4: BR004 | G4: Sample largedeposit | H4: U015 | I4: 46305.401 | J4: Approved | K4: U016 | L4: 46305.431 | N4: G20261010-00057
A5: AP000004 | B5: Reversal | C5: 0050000443 | E5: 165108 | F5: BR005 | G5: Sample reversal | H5: U002 | I5: 46301.392 | J5: Approved | K5: U003 | L5: 46301.454 | N5: G20261006-00059
A6: AP000005 | B6: LargeWithdrawal | C6: 0020000002 | E6: 8000000 | F6: BR002 | G6: Sample largewithdrawal | H6: U008 | I6: 46307.407 | J6: Pending
A7: AP000006 | B7: LargeWithdrawal | C7: 0060000022 | E7: 8000000 | F7: BR006 | G7: Sample largewithdrawal | H7: U021 | I7: 46307.389 | J7: Pending
A8: AP000007 | B8: LargeTransfer | C8: 0020000002 | D8: 0040000017 | E8: 12000000 | F8: BR002 | G8: Sample largetransfer | H8: U009 | I8: 46307.409 | J8: Pending
A9: AP000008 | B9: CashShipment | E9: 200000000 | F9: BR012 | G9: Sample cashshipment | H9: U002 | I9: 46307.406 | J9: Pending
A10: AP000009 | B10: LargeWithdrawal | C10: 0030000045 | E10: 9000000 | F10: BR003 | G10: Sample largewithdrawal | H10: U012 | I10: 46304.415 | J10: Rejected | K10: U013 | L10: 46304.419 | M10: Customer could not show identification

Sheet Journal
A1: JournalID | B1: PostDate | C1: Description | D1: JournalType | E1: GroupID | F1: Status | G1: ReversalOf | H1: CreatedBy | I1: CreatedAt
A2: J00000001 | B2: 46295 | C2: Share capital paid in | D2: Opening | E2: G20260930-00001 | F2: Posted | H2: U001 | I2: 46295.685
A3: J00000002 | B3: 46295 | C3: Head office cash from treasury | D3: Opening | E3: G20260930-00001 | F3: Posted | H3: U001 | I3: 46295.572
A4: J00000003 | B4: 46295 | C4: Opening cash for Hlaing Branch | D4: Opening | E4: G20260930-00001 | F4: Posted | H4: U001 | I4: 46295.503
A5: J00000004 | B5: 46295 | C5: Opening cash for Thingangyun Branch | D5: Opening | E5: G20260930-00001 | F5: Posted | H5: U001 | I5: 46295.607
A6: J00000005 | B6: 46295 | C6: Opening cash for Chanayethazan Branch | D6: Opening | E6: G20260930-00001 | F6: Posted | H6: U001 | I6: 46295.605
A7: J00000006 | B7: 46295 | C7: Opening cash for Aungmyaythazan Branch | D7: Opening | E7: G20260930-00001 | F7: Posted | H7: U001 | I7: 46295.633
A8: J00000007 | B8: 46295 | C8: Opening cash for Zabuthiri Branch | D8: Opening | E8: G20260930-00001 | F8: Posted | H8: U001 | I8: 46295.61
A9: J00000008 | B9: 46295 | C9: Opening cash for Mawlamyine Branch | D9: Opening | E9: G20260930-00001 | F9: Posted | H9: U001 | I9: 46295.403
A10: J00000009 | B10: 46295 | C10: Opening cash for Taunggyi Branch | D10: Opening | E10: G20260930-00001 | F10: Posted | H10: U001 | I10: 46295.456
A11: J00000010 | B11: 46295 | C11: Opening cash for Pyin Oo Lwin Branch | D11: Opening | E11: G20260930-00001 | F11: Posted | H11: U001 | I11: 46295.393
A12: J00000011 | B12: 46295 | C12: Opening cash for Kyaukse Branch | D12: Opening | E12: G20260930-00001 | F12: Posted | H12: U001 | I12: 46295.574
A13: J00000012 | B13: 46295 | C13: Opening cash for Meiktila Branch | D13: Opening | E13: G20260930-00001 | F13: Posted | H13: U001 | I13: 46295.471
... A703: J00000702 | B703: 46307 | C703: Interbank settlement (simulated) | D703: InterbankSettle | E703: G20261012-00055 | F703: Posted | H703: U002 | I703: 46307.479
A704: J00000703 | B704: 46301 | C704: Reversal of TX20261005-00001 | D704: Reversal | E704: G20261006-00059 | F704: Posted | G704: J00000246 | H704: U002 | I704: 46301.662

Sheet JournalLines
A1: LineID | B1: JournalID | C1: BranchID | D1: GLCode | E1: AccountNo | F1: Currency | G1: Debit | H1: Credit | I1: FxRate | J1: ForeignAmount
A2: L0000001 | B2: J00000001 | C2: BR001 | D2: 1100 | F2: MMK | G2: 20000000000 | H2: 0
A3: L0000002 | B3: J00000001 | C3: BR001 | D3: 3000 | F3: MMK | G3: 0 | H3: 20000000000
A4: L0000003 | B4: J00000002 | C4: BR001 | D4: 1000 | F4: MMK | G4: 4500000000 | H4: 0
A5: L0000004 | B5: J00000002 | C5: BR001 | D5: 1100 | F5: MMK | G5: 0 | H5: 4500000000
A6: L0000005 | B6: J00000003 | C6: BR002 | D6: 1000 | F6: MMK | G6: 300000000 | H6: 0
A7: L0000006 | B7: J00000003 | C7: BR002 | D7: 1900 | F7: MMK | G7: 0 | H7: 300000000
A8: L0000007 | B8: J00000003 | C8: BR001 | D8: 1900 | F8: MMK | G8: 300000000 | H8: 0
A9: L0000008 | B9: J00000003 | C9: BR001 | D9: 1000 | F9: MMK | G9: 0 | H9: 300000000
A10: L0000009 | B10: J00000004 | C10: BR003 | D10: 1000 | F10: MMK | G10: 300000000 | H10: 0
A11: L0000010 | B11: J00000004 | C11: BR003 | D11: 1900 | F11: MMK | G11: 0 | H11: 300000000
A12: L0000011 | B12: J00000004 | C12: BR001 | D12: 1900 | F12: MMK | G12: 300000000 | H12: 0
A13: L0000012 | B13: J00000004 | C13: BR001 | D13: 1000 | F13: MMK | G13: 0 | H13: 300000000
... A61: L0000060 | B61: J00000016 | C61: BR001 | D61: 1000 | F61: MMK | G61: 0 | H61: 120000000
A62: L0000061 | B62: J00000017 | C62: BR001 | D62: 2000 | E62: 0010000009 | F62: MMK | G62: 0 | H62: 1602465
A63: L0000062 | B63: J00000017 | C63: BR001 | D63: 2010 | E63: 0010000010 | F63: MMK | G63: 0 | H63: 1167172
A64: L0000063 | B64: J00000017 | C64: BR001 | D64: 2000 | E64: 0010000011 | F64: MMK | G64: 0 | H64: 3940665
A65: L0000064 | B65: J00000017 | C65: BR001 | D65: 2010 | E65: 0010000024 | F65: MMK | G65: 0 | H65: 25028259
A66: L0000065 | B66: J00000017 | C66: BR001 | D66: 2000 | E66: 0010000025 | F66: MMK | G66: 0 | H66: 1712602
A67: L0000066 | B67: J00000017 | C67: BR001 | D67: 2000 | E67: 0010000031 | F67: MMK | G67: 0 | H67: 5000000
A68: L0000067 | B68: J00000017 | C68: BR001 | D68: 2000 | E68: 0010000036 | F68: MMK | G68: 0 | H68: 5612344
A69: L0000068 | B69: J00000017 | C69: BR001 | D69: 2000 | E69: 0010000076 | F69: MMK | G69: 0 | H69: 4688765
A70: L0000069 | B70: J00000017 | C70: BR001 | D70: 2010 | E70: 0010000092 | F70: MMK | G70: 0 | H70: 18143711
A71: L0000070 | B71: J00000017 | C71: BR001 | D71: 2000 | E71: 0010000120 | F71: MMK | G71: 0 | H71: 2387847
A72: L0000071 | B72: J00000017 | C72: BR001 | D72: 2000 | E72: 0010000130 | F72: MMK | G72: 0 | H72: 928543
A73: L0000072 | B73: J00000017 | C73: BR001 | D73: 2010 | E73: 0010000131 | F73: MMK | G73: 0 | H73: 6778299
... A87: L0000086 | B87: J00000017 | C87: BR001 | D87: 2020 | E87: 0010000422 | F87: MMK | G87: 0 | H87: 6675443
A88: L0000087 | B88: J00000017 | C88: BR001 | D88: 1900 | F88: MMK | G88: 152266065 | H88: 0
A89: L0000088 | B89: J00000018 | C89: BR002 | D89: 2010 | E89: 0020000002 | F89: MMK | G89: 0 | H89: 48110974
A90: L0000089 | B90: J00000018 | C90: BR002 | D90: 2000 | E90: 0020000005 | F90: MMK | G90: 0 | H90: 469866
A91: L0000090 | B91: J00000018 | C91: BR002 | D91: 2000 | E91: 0020000013 | F91: MMK | G91: 0 | H91: 558234
A92: L0000091 | B92: J00000018 | C92: BR002 | D92: 2000 | E92: 0020000030 | F92: MMK | G92: 0 | H92: 450886
A93: L0000092 | B93: J00000018 | C93: BR002 | D93: 2000 | E93: 0020000034 | F93: MMK | G93: 0 | H93: 302269
A94: L0000093 | B94: J00000018 | C94: BR002 | D94: 2000 | E94: 0020000041 | F94: MMK | G94: 0 | H94: 7479468
A95: L0000094 | B95: J00000018 | C95: BR002 | D95: 2000 | E95: 0020000069 | F95: MMK | G95: 0 | H95: 2874048
A96: L0000095 | B96: J00000018 | C96: BR002 | D96: 2010 | E96: 0020000070 | F96: MMK | G96: 0 | H96: 776704
A97: L0000096 | B97: J00000018 | C97: BR002 | D97: 2010 | E97: 0020000085 | F97: MMK | G97: 0 | H97: 41328712
A98: L0000097 | B98: J00000018 | C98: BR002 | D98: 2000 | E98: 0020000086 | F98: MMK | G98: 0 | H98: 1418364
A99: L0000098 | B99: J00000018 | C99: BR002 | D99: 2000 | E99: 0020000096 | F99: MMK | G99: 0 | H99: 11464349
A100: L0000099 | B100: J00000018 | C100: BR002 | D100: 2010 | E100: 0020000097 | F100: MMK | G100: 0 | H100: 7385210
...

Sheet DailyClose
A1: BusinessDate | B1: RunAt | C1: AccountsAccrued | D1: InterestAccrued | E1: InterbankSettled | F1: FDMatured | G1: DormantMarked | H1: ChecksPassed | I1: Notes
A2: 46296 | B2: 46296.75 | C2: 436 | D2: 313164.74 | E2: 0 | F2: 0 | G2: 0 | H2: Yes | I2: Sample end of day
A3: 46297 | B3: 46297.75 | C3: 437 | D3: 314606.51 | E3: 1 | F3: 0 | G3: 0 | H3: Yes | I3: Sample end of day
A4: 46298 | B4: 46298.75 | C4: 438 | D4: 318656.45 | E4: 1 | F4: 0 | G4: 0 | H4: Yes | I4: Sample end of day
A5: 46299 | B5: 46299.75 | C5: 439 | D5: 319109.29 | E5: 2 | F5: 0 | G5: 0 | H5: Yes | I5: Sample end of day
A6: 46300 | B6: 46300.75 | C6: 440 | D6: 319918.51 | E6: 4 | F6: 0 | G6: 0 | H6: Yes | I6: Sample end of day
A7: 46301 | B7: 46301.75 | C7: 441 | D7: 320748.9 | E7: 2 | F7: 0 | G7: 0 | H7: Yes | I7: Sample end of day
A8: 46302 | B8: 46302.75 | C8: 442 | D8: 322720.97 | E8: 1 | F8: 0 | G8: 0 | H8: Yes | I8: Sample end of day
A9: 46303 | B9: 46303.75 | C9: 443 | D9: 323019.02 | E9: 3 | F9: 0 | G9: 0 | H9: Yes | I9: Sample end of day
A10: 46304 | B10: 46304.75 | C10: 444 | D10: 325635.81 | E10: 4 | F10: 0 | G10: 0 | H10: Yes | I10: Sample end of day
A11: 46305 | B11: 46305.75 | C11: 444 | D11: 326803.14 | E11: 2 | F11: 0 | G11: 0 | H11: Yes | I11: Sample end of day
A12: 46306 | B12: 46306.75 | C12: 444 | D12: 327846.59 | E12: 2 | F12: 0 | G12: 0 | H12: Yes | I12: Sample end of day
A13: 46307 | B13: 46307.75 | C13: 444 | D13: 328963.65 | E13: 1 | F13: 0 | G13: 0 | H13: Yes | I13: Sample end of day

Sheet Audit
A1: AuditID | B1: Timestamp | C1: UserID | D1: Action | E1: Target | F1: Detail

Sheet Log
A1: Timestamp | B1: Level | C1: Procedure | D1: Message

Sheet Currencies
A1: Code | B1: Name | C1: Decimals | D1: IsBase
A2: MMK | B2: Myanmar kyat | C2: 0 | D2: Yes
A3: USD | B3: US dollar | C3: 2 | D3: No
A4: JPY | B4: Japanese yen | C4: 0 | D4: No
A5: THB | B5: Thai baht | C5: 2 | D5: No
A6: SGD | B6: Singapore dollar | C6: 2 | D6: No

Sheet ExchangeRates
A1: RateDate | B1: Currency | C1: BuyRate | D1: SellRate | E1: MidRate
A2: 46279 | B2: USD | C2: 2135.55 | D2: 2178.69 | E2: 2157.12
A3: 46279 | B3: JPY | C3: 14.48 | D3: 14.78 | E3: 14.63
A4: 46279 | B4: THB | C4: 62.27 | D4: 63.53 | E4: 62.9
A5: 46279 | B5: SGD | C5: 1635.37 | D5: 1668.41 | E5: 1651.89
A6: 46280 | B6: USD | C6: 2128.56 | D6: 2171.57 | E6: 2150.07
A7: 46280 | B7: JPY | C7: 14.52 | D7: 14.82 | E7: 14.67
A8: 46280 | B8: THB | C8: 62.28 | D8: 63.54 | E8: 62.91
A9: 46280 | B9: SGD | C9: 1640.71 | D9: 1673.85 | E9: 1657.28
A10: 46281 | B10: USD | C10: 2126.11 | D10: 2169.06 | E10: 2147.58
A11: 46281 | B11: JPY | C11: 14.49 | D11: 14.78 | E11: 14.64
A12: 46281 | B12: THB | C12: 62.3 | D12: 63.56 | E12: 62.93
A13: 46281 | B13: SGD | C13: 1640.74 | D13: 1673.89 | E13: 1657.32
... A121: 46308 | B121: SGD | C121: 1659.39 | D121: 1692.92 | E121: 1676.16

Sheet TaxRates
A1: TaxCode | B1: Name | C1: Rate | D1: AppliesTo | E1: GLCode | F1: EffectiveFrom
A2: WHT_INTEREST | B2: Withholding tax on deposit interest | C2: 0.1 | D2: Interest paid to customers | E2: 2200 | F2: 46023
A3: COMMERCIAL_FEES | B3: Commercial tax on fee income | C3: 0.05 | D3: Fee income | E3: 2210 | F3: 46023
A4: INCOME_TAX | B4: Income tax on annual profit | C4: 0.25 | D4: Annual profit | E4: 2220 | F4: 46023
A5: PAYROLL_SSB | B5: Employer social security contribution | C5: 0.03 | D5: Salaries | E5: 2230 | F5: 46023

Sheet BranchCosts
A1: CostID | B1: BranchID | C1: CostType | D1: Description | E1: Frequency | F1: Amount | G1: GLCode | H1: StartDate | I1: EndDate | J1: Status
A2: BC0001 | B2: BR001 | C2: Electricity | D2: Electricity for Head Office | E2: Monthly | F2: 5683000 | G2: 5210 | H2: 39539 | J2: Active
A3: BC0002 | B3: BR001 | C3: Water | D3: Water for Head Office | E3: Monthly | F3: 358000 | G3: 5211 | H3: 39539 | J3: Active
A4: BC0003 | B4: BR001 | C4: Internet and phone | D4: Internet and phone for Head Office | E4: Monthly | F4: 3658000 | G4: 5212 | H4: 39539 | J4: Active
A5: BC0004 | B5: BR001 | C5: Security guard service | D5: Security guard service for Head Office | E5: Monthly | F5: 3923000 | G5: 5230 | H5: 39539 | J5: Active
A6: BC0005 | B6: BR001 | C6: Cleaning service | D6: Cleaning service for Head Office | E6: Monthly | F6: 1819000 | G6: 5230 | H6: 39539 | J6: Active
A7: BC0006 | B7: BR001 | C7: Maintenance contract | D7: Maintenance contract for Head Office | E7: Monthly | F7: 2879000 | G7: 5220 | H7: 39539 | J7: Active
A8: BC0007 | B8: BR001 | C8: Stationery and supplies | D8: Stationery and supplies for Head Office | E8: Monthly | F8: 1735000 | G8: 5270 | H8: 39539 | J8: Active
A9: BC0008 | B9: BR001 | C9: Generator fuel | D9: Generator fuel for Head Office | E9: Monthly | F9: 1503000 | G9: 5280 | H9: 39539 | J9: Active
A10: BC0009 | B10: BR001 | C10: Insurance | D10: Insurance for Head Office | E10: Yearly | F10: 31005000 | G10: 5240 | H10: 39539 | J10: Active
A11: BC0010 | B11: BR001 | C11: Property tax and licences | D11: Property tax and licences for Head Office | E11: Yearly | F11: 11761000 | G11: 5260 | H11: 39539 | J11: Active
A12: BC0011 | B12: BR002 | C12: Electricity | D12: Electricity for Hlaing Branch | E12: Monthly | F12: 1842000 | G12: 5210 | H12: 40330 | J12: Active
A13: BC0012 | B13: BR002 | C13: Water | D13: Water for Hlaing Branch | E13: Monthly | F13: 147000 | G13: 5211 | H13: 40330 | J13: Active
... A151: BC0150 | B151: BR015 | C151: Rent | D151: Rent for Nyaung-U Branch | E151: Monthly | F151: 1903000 | G151: 5200 | H151: 43831 | J151: Active

Sheet FixedAssets
A1: AssetID | B1: BranchID | C1: AssetType | D1: Description | E1: AcquireDate | F1: Cost | G1: UsefulLifeMonths | H1: ResidualValue | I1: DepMethod | J1: AccumDepAt20260930 | K1: Status
A2: FA0001 | B2: BR001 | C2: Building | D2: Building, Head Office | E2: 43958 | F2: 8000000000 | G2: 480 | H2: 0 | I2: StraightLine | J2: 1266666666 | K2: InUse
A3: FA0002 | B3: BR001 | C3: Vault and safe | D3: Vault and safe, Head Office | E3: 45644 | F3: 45000000 | G3: 240 | H3: 2250000 | I3: StraightLine | J3: 3740625 | K3: InUse
A4: FA0003 | B4: BR001 | C4: Generator | D4: Generator, Head Office | E4: 45614 | F4: 35000000 | G4: 120 | H4: 1750000 | I4: StraightLine | J4: 6095833 | K4: InUse
A5: FA0004 | B5: BR001 | C5: Computers and network | D5: Computers and network, Head Office | E5: 45407 | F5: 28000000 | G5: 48 | H5: 1400000 | I5: StraightLine | J5: 16070833 | K5: InUse
A6: FA0005 | B6: BR001 | C6: Furniture | D6: Furniture, Head Office | E6: 45538 | F6: 15000000 | G6: 96 | H6: 750000 | I6: StraightLine | J6: 3562500 | K6: InUse
A7: FA0006 | B7: BR001 | C7: Air conditioning | D7: Air conditioning, Head Office | E7: 44427 | F7: 12000000 | G7: 96 | H7: 600000 | I7: StraightLine | J7: 7243750 | K7: InUse
A8: FA0007 | B8: BR001 | C8: Vehicle | D8: Vehicle, Head Office | E8: 43814 | F8: 90000000 | G8: 96 | H8: 4500000 | I8: StraightLine | J8: 72140625 | K8: InUse
A9: FA0008 | B9: BR002 | C9: Vault and safe | D9: Vault and safe, Hlaing Branch | E9: 44715 | F9: 45000000 | G9: 240 | H9: 2250000 | I9: StraightLine | J9: 9084375 | K9: InUse
A10: FA0009 | B10: BR002 | C10: Generator | D10: Generator, Hlaing Branch | E10: 43946 | F10: 35000000 | G10: 120 | H10: 1750000 | I10: StraightLine | J10: 21335416 | K10: InUse
A11: FA0010 | B11: BR002 | C11: Computers and network | D11: Computers and network, Hlaing Branch | E11: 44552 | F11: 28000000 | G11: 48 | H11: 1400000 | I11: StraightLine | J11: 26600000 | K11: InUse
A12: FA0011 | B12: BR002 | C12: Furniture | D12: Furniture, Hlaing Branch | E12: 44801 | F12: 15000000 | G12: 96 | H12: 750000 | I12: StraightLine | J12: 7273437 | K12: InUse
A13: FA0012 | B13: BR002 | C13: Air conditioning | D13: Air conditioning, Hlaing Branch | E13: 44140 | F13: 12000000 | G13: 96 | H13: 600000 | I13: StraightLine | J13: 8312500 | K13: InUse
... A90: FA0089 | B90: BR015 | C90: Air conditioning | D90: Air conditioning, Nyaung-U Branch | E90: 45777 | F90: 5000000 | G90: 96 | H90: 250000 | I90: StraightLine | J90: 841145 | K90: InUse
